2021-06-13 19:58:23,189 ERROR: Exception on /user/susan [GET] [in c:\users\acer\microblog\.venv\lib\site-packages\flask\app.py:1891]
Traceback (most recent call last):
  File "c:\users\acer\microblog\.venv\lib\site-packages\flask\app.py", line 2447, in wsgi_app
    response = self.full_dispatch_request()
  File "c:\users\acer\microblog\.venv\lib\site-packages\flask\app.py", line 1952, in full_dispatch_request
    rv = self.handle_user_exception(e)
  File "c:\users\acer\microblog\.venv\lib\site-packages\flask\app.py", line 1821, in handle_user_exception
    reraise(exc_type, exc_value, tb)
  File "c:\users\acer\microblog\.venv\lib\site-packages\flask\_compat.py", line 39, in reraise
    raise value
  File "c:\users\acer\microblog\.venv\lib\site-packages\flask\app.py", line 1950, in full_dispatch_request
    rv = self.dispatch_request()
  File "c:\users\acer\microblog\.venv\lib\site-packages\flask\app.py", line 1936, in dispatch_request
    return self.view_functions[rule.endpoint](**req.view_args)
  File "c:\users\acer\microblog\.venv\lib\site-packages\flask_login\utils.py", line 272, in decorated_view
    return func(*args, **kwargs)
  File "C:\Users\acer\microblog\app\main\routes.py", line 46, in user
    return render_template('user.html',user=user,posts=posts.items,form=form,next_url=next_url,prev_url=prev_url)
  File "c:\users\acer\microblog\.venv\lib\site-packages\flask\templating.py", line 138, in render_template
    ctx.app.jinja_env.get_or_select_template(template_name_or_list),
  File "c:\users\acer\microblog\.venv\lib\site-packages\jinja2\environment.py", line 930, in get_or_select_template
    return self.get_template(template_name_or_list, parent, globals)
  File "c:\users\acer\microblog\.venv\lib\site-packages\jinja2\environment.py", line 883, in get_template
    return self._load_template(name, self.make_globals(globals))
  File "c:\users\acer\microblog\.venv\lib\site-packages\jinja2\environment.py", line 857, in _load_template
    template = self.loader.load(self, name, globals)
  File "c:\users\acer\microblog\.venv\lib\site-packages\jinja2\loaders.py", line 127, in load
    code = environment.compile(source, name, filename)
  File "c:\users\acer\microblog\.venv\lib\site-packages\jinja2\environment.py", line 638, in compile
    self.handle_exception(source=source_hint)
  File "c:\users\acer\microblog\.venv\lib\site-packages\jinja2\environment.py", line 832, in handle_exception
    reraise(*rewrite_traceback_stack(source=source))
  File "c:\users\acer\microblog\.venv\lib\site-packages\jinja2\_compat.py", line 28, in reraise
    raise value.with_traceback(tb)
  File "C:\Users\acer\microblog\app\templates\user.html", line 22, in template
    {{ form.submit(value=_('Unfollow') class_='btn btn-default') }}
jinja2.exceptions.TemplateSyntaxError: expected token ',', got 'class_'
2021-06-13 19:59:19,083 INFO: Microblog startup [in C:\Users\acer\microblog\app\__init__.py:72]
2021-06-13 19:59:55,671 ERROR: Exception on /auth/reset_password_request [GET] [in c:\users\acer\microblog\.venv\lib\site-packages\flask\app.py:1891]
Traceback (most recent call last):
  File "c:\users\acer\microblog\.venv\lib\site-packages\flask\app.py", line 2447, in wsgi_app
    response = self.full_dispatch_request()
  File "c:\users\acer\microblog\.venv\lib\site-packages\flask\app.py", line 1952, in full_dispatch_request
    rv = self.handle_user_exception(e)
  File "c:\users\acer\microblog\.venv\lib\site-packages\flask\app.py", line 1821, in handle_user_exception
    reraise(exc_type, exc_value, tb)
  File "c:\users\acer\microblog\.venv\lib\site-packages\flask\_compat.py", line 39, in reraise
    raise value
  File "c:\users\acer\microblog\.venv\lib\site-packages\flask\app.py", line 1950, in full_dispatch_request
    rv = self.dispatch_request()
  File "c:\users\acer\microblog\.venv\lib\site-packages\flask\app.py", line 1936, in dispatch_request
    return self.view_functions[rule.endpoint](**req.view_args)
  File "C:\Users\acer\microblog\app\auth\routes.py", line 60, in reset_password_request
    return render_template('auth/reset_password_request.html',form=form,title=_('Reset'))
  File "c:\users\acer\microblog\.venv\lib\site-packages\flask\templating.py", line 138, in render_template
    ctx.app.jinja_env.get_or_select_template(template_name_or_list),
  File "c:\users\acer\microblog\.venv\lib\site-packages\jinja2\environment.py", line 930, in get_or_select_template
    return self.get_template(template_name_or_list, parent, globals)
  File "c:\users\acer\microblog\.venv\lib\site-packages\jinja2\environment.py", line 883, in get_template
    return self._load_template(name, self.make_globals(globals))
  File "c:\users\acer\microblog\.venv\lib\site-packages\jinja2\environment.py", line 857, in _load_template
    template = self.loader.load(self, name, globals)
  File "c:\users\acer\microblog\.venv\lib\site-packages\jinja2\loaders.py", line 127, in load
    code = environment.compile(source, name, filename)
  File "c:\users\acer\microblog\.venv\lib\site-packages\jinja2\environment.py", line 638, in compile
    self.handle_exception(source=source_hint)
  File "c:\users\acer\microblog\.venv\lib\site-packages\jinja2\environment.py", line 832, in handle_exception
    reraise(*rewrite_traceback_stack(source=source))
  File "c:\users\acer\microblog\.venv\lib\site-packages\jinja2\_compat.py", line 28, in reraise
    raise value.with_traceback(tb)
  File "C:\Users\acer\microblog\app\templates\auth\reset_password_request.html", line 2, in template
    {% extends 'bootstrap/wtf.html' as wtf %}
jinja2.exceptions.TemplateSyntaxError: expected token 'end of statement block', got 'as'
2021-06-13 20:02:26,388 INFO: Microblog startup [in C:\Users\acer\microblog\app\__init__.py:72]
2021-06-13 20:02:37,881 ERROR: Exception on /auth/reset_password_request [POST] [in c:\users\acer\microblog\.venv\lib\site-packages\flask\app.py:1891]
Traceback (most recent call last):
  File "c:\users\acer\microblog\.venv\lib\site-packages\flask\app.py", line 2447, in wsgi_app
    response = self.full_dispatch_request()
  File "c:\users\acer\microblog\.venv\lib\site-packages\flask\app.py", line 1952, in full_dispatch_request
    rv = self.handle_user_exception(e)
  File "c:\users\acer\microblog\.venv\lib\site-packages\flask\app.py", line 1821, in handle_user_exception
    reraise(exc_type, exc_value, tb)
  File "c:\users\acer\microblog\.venv\lib\site-packages\flask\_compat.py", line 39, in reraise
    raise value
  File "c:\users\acer\microblog\.venv\lib\site-packages\flask\app.py", line 1950, in full_dispatch_request
    rv = self.dispatch_request()
  File "c:\users\acer\microblog\.venv\lib\site-packages\flask\app.py", line 1936, in dispatch_request
    return self.view_functions[rule.endpoint](**req.view_args)
  File "C:\Users\acer\microblog\app\auth\routes.py", line 57, in reset_password_request
    send_password_reset_email(user)
  File "C:\Users\acer\microblog\app\auth\email.py", line 7, in send_password_reset_email
    token = user.get_reset_password_token()
  File "C:\Users\acer\microblog\app\models.py", line 55, in get_reset_password_token
    return jwt.encode( {'reset_password':self.id,'exp':time()+expires_in},app.config['SECRET_KEY'],algorithm='HS256')
NameError: name 'app' is not defined
2021-06-13 20:03:31,190 INFO: Microblog startup [in C:\Users\acer\microblog\app\__init__.py:72]
2021-06-13 20:03:40,043 ERROR: Exception on /auth/reset_password_request [POST] [in c:\users\acer\microblog\.venv\lib\site-packages\flask\app.py:1891]
Traceback (most recent call last):
  File "c:\users\acer\microblog\.venv\lib\site-packages\flask\app.py", line 2447, in wsgi_app
    response = self.full_dispatch_request()
  File "c:\users\acer\microblog\.venv\lib\site-packages\flask\app.py", line 1952, in full_dispatch_request
    rv = self.handle_user_exception(e)
  File "c:\users\acer\microblog\.venv\lib\site-packages\flask\app.py", line 1821, in handle_user_exception
    reraise(exc_type, exc_value, tb)
  File "c:\users\acer\microblog\.venv\lib\site-packages\flask\_compat.py", line 39, in reraise
    raise value
  File "c:\users\acer\microblog\.venv\lib\site-packages\flask\app.py", line 1950, in full_dispatch_request
    rv = self.dispatch_request()
  File "c:\users\acer\microblog\.venv\lib\site-packages\flask\app.py", line 1936, in dispatch_request
    return self.view_functions[rule.endpoint](**req.view_args)
  File "C:\Users\acer\microblog\app\auth\routes.py", line 57, in reset_password_request
    send_password_reset_email(user)
  File "C:\Users\acer\microblog\app\auth\email.py", line 7, in send_password_reset_email
    token = user.get_reset_password_token()
  File "C:\Users\acer\microblog\app\models.py", line 55, in get_reset_password_token
    return jwt.encode( {'reset_password':self.id,'exp':time()+expires_in},current_app.config['SECRET_KEY'],algorithm='HS256')
NameError: name 'current_app' is not defined
2021-06-13 20:04:09,252 INFO: Microblog startup [in C:\Users\acer\microblog\app\__init__.py:72]
2021-06-13 20:19:30,158 INFO: Microblog startup [in C:\Users\acer\microblog\app\__init__.py:72]
